<?xml version="1.0" ?>
<!-- =================================================================================== -->
<!-- |    This document was autogenerated by xacro from gvrbot.urdf.xacro              | -->
<!-- |    EDITING THIS FILE BY HAND IS NOT RECOMMENDED                                 | -->
<!-- =================================================================================== -->
<robot name="gvrbot" xmlns:interface="http://www.ros.org/wiki/xacro/#interface" xmlns:xacro="http://www.ros.org/wiki/xacro">
  <!-- radius - socket height -->
  <material name="army_green">
    <color rgba="0.164705882353 0.180392156863 0.0705882352941 1.0"/>
  </material>
  <!-- Links and Joints (i.e., the robot) -->
  <link name="base_footprint"/>
  <joint name="bf_to_bl" type="fixed">
    <origin rpy="0.0 0.0 0.0" xyz="0.0 0.0 -0.17"/>
    <parent link="base_link"/>
    <child link="base_footprint"/>
  </joint>
  <link name="base_link"/>
  <joint name="chasis_to_bl" type="fixed">
    <origin rpy="0.0 0.0 0.0" xyz="0.0 0.0 0.0"/>
    <parent link="base_link"/>
    <child link="chasis_link"/>
  </joint>
  <link name="chasis_link">
    <inertial>
      <mass value="25.0"/>
      <origin rpy="0 0 0" xyz="0.0 0.0 0.0"/>
      <inertia ixx="0.810208333333" ixy="0.7125" ixz="0.201875" iyy="0.810208333333" iyz="0.159375" izz="0.810208333333"/>
    </inertial>
    <!-- compare the two visual pieces until they match up in size then delete the mesh -->
    <visual>
      <origin rpy="0 0 1.57" xyz="0.33 0.0 -0.17"/>
      <geometry>
        <mesh filename="package://gvrbot/models/meshes/gvrbot_base.STL"/>
      </geometry>
      <material name="army_green"/>
    </visual>
    <!--visual>
                <origin xyz="0.0 0.0 -0.085" rpy="0 0 0" />
                <geometry>
                    <box size="${base_size_x} ${base_size_y} ${base_size_z}" />
                </geometry>
                <Green />
            </visual-->
    <collision>
      <origin rpy="0 0 0" xyz="0.0 0.0 -0.085"/>
      <geometry>
        <box size="0.38 0.3 0.085"/>
      </geometry>
    </collision>
  </link>
  <joint name="left_0_wheel_joint" type="continuous">
    <origin rpy="0 0 0" xyz="0.251 0.15 -0.085"/>
    <parent link="base_link"/>
    <child link="left_0_wheel_link"/>
    <axis xyz="0 1 0"/>
    <limit effort="100" velocity="100"/>
    <joint_properties damping="0.0" friction="0.0"/>
    <anchor xyz="0 0 0"/>
  </joint>
  <link name="left_0_wheel_link">
    <inertial>
      <mass value="0.1"/>
      <origin xyz=" 0 0 0 "/>
      <inertia ixx="0.00012411765597" ixy="0.0" ixz="0.0" iyy="0.00015218160428" iyz="0.0" izz="0.00011763977943"/>
    </inertial>
    <collision>
      <origin rpy="-1.570795 0 0" xyz="0 0 0"/>
      <geometry>
        <cylinder length="0.0825" radius="0.085"/>
        <!--<box size="1.0 0.5 0.1" />-->
      </geometry>
      <!--<material name="MTWheelColMat"/>-->
    </collision>
  </link>
  <gazebo reference="left_0_wheel_link">
    <mu1>1.0</mu1>
    <mu2>1.0</mu2>
    <kp>1000000.0</kp>
    <kd>100.0</kd>
    <minDepth>0.001</minDepth>
    <maxVel>1.0</maxVel>
    <!--<fdir1>1 0 0</fdir1>-->
    <!--<maxVel>1.0</maxVel>-->
  </gazebo>
  <transmission name="left_0_wheel_trans" type="pr2_mechanism_model/SimpleTransmission">
    <actuator name="left_0_motor_link"/>
    <joint name="left_0_wheel_joint"/>
    <mechanicalReduction>1.0</mechanicalReduction>
    <motorTorqueConstant>1</motorTorqueConstant>
  </transmission>
  <joint name="left_1_wheel_joint" type="continuous">
    <origin rpy="0 0 0" xyz="0.0 0.15 -0.09"/>
    <parent link="base_link"/>
    <child link="left_1_wheel_link"/>
    <axis xyz="0 1 0"/>
    <limit effort="100" velocity="100"/>
    <joint_properties damping="0.0" friction="0.0"/>
    <anchor xyz="0 0 0"/>
  </joint>
  <link name="left_1_wheel_link">
    <inertial>
      <mass value="0.1"/>
      <origin xyz=" 0 0 0 "/>
      <inertia ixx="0.00012411765597" ixy="0.0" ixz="0.0" iyy="0.00015218160428" iyz="0.0" izz="0.00011763977943"/>
    </inertial>
    <collision>
      <origin rpy="-1.570795 0 0" xyz="0 0 0"/>
      <geometry>
        <cylinder length="0.0825" radius="0.085"/>
        <!--<box size="1.0 0.5 0.1" />-->
      </geometry>
      <!--<material name="MTWheelColMat"/>-->
    </collision>
  </link>
  <gazebo reference="left_1_wheel_link">
    <mu1>1.0</mu1>
    <mu2>1.0</mu2>
    <kp>1000000.0</kp>
    <kd>100.0</kd>
    <minDepth>0.001</minDepth>
    <maxVel>1.0</maxVel>
    <!--<fdir1>1 0 0</fdir1>-->
    <!--<maxVel>1.0</maxVel>-->
  </gazebo>
  <transmission name="left_1_wheel_trans" type="pr2_mechanism_model/SimpleTransmission">
    <actuator name="left_1_motor_link"/>
    <joint name="left_1_wheel_joint"/>
    <mechanicalReduction>1.0</mechanicalReduction>
    <motorTorqueConstant>1</motorTorqueConstant>
  </transmission>
  <joint name="left_2_wheel_joint" type="continuous">
    <origin rpy="0 0 0" xyz="-0.251 0.15 -0.085"/>
    <parent link="base_link"/>
    <child link="left_2_wheel_link"/>
    <axis xyz="0 1 0"/>
    <limit effort="100" velocity="100"/>
    <joint_properties damping="0.0" friction="0.0"/>
    <anchor xyz="0 0 0"/>
  </joint>
  <link name="left_2_wheel_link">
    <inertial>
      <mass value="0.1"/>
      <origin xyz=" 0 0 0 "/>
      <inertia ixx="0.00012411765597" ixy="0.0" ixz="0.0" iyy="0.00015218160428" iyz="0.0" izz="0.00011763977943"/>
    </inertial>
    <collision>
      <origin rpy="-1.570795 0 0" xyz="0 0 0"/>
      <geometry>
        <cylinder length="0.0825" radius="0.085"/>
        <!--<box size="1.0 0.5 0.1" />-->
      </geometry>
      <!--<material name="MTWheelColMat"/>-->
    </collision>
  </link>
  <gazebo reference="left_2_wheel_link">
    <mu1>1.0</mu1>
    <mu2>1.0</mu2>
    <kp>1000000.0</kp>
    <kd>100.0</kd>
    <minDepth>0.001</minDepth>
    <maxVel>1.0</maxVel>
    <!--<fdir1>1 0 0</fdir1>-->
    <!--<maxVel>1.0</maxVel>-->
  </gazebo>
  <transmission name="left_2_wheel_trans" type="pr2_mechanism_model/SimpleTransmission">
    <actuator name="left_2_motor_link"/>
    <joint name="left_2_wheel_joint"/>
    <mechanicalReduction>1.0</mechanicalReduction>
    <motorTorqueConstant>1</motorTorqueConstant>
  </transmission>
  <joint name="right_0_wheel_joint" type="continuous">
    <origin rpy="0 0 0" xyz="0.251 -0.15 -0.085"/>
    <parent link="base_link"/>
    <child link="right_0_wheel_link"/>
    <axis xyz="0 1 0"/>
    <limit effort="100" velocity="100"/>
    <joint_properties damping="0.0" friction="0.0"/>
    <anchor xyz="0 0 0"/>
  </joint>
  <link name="right_0_wheel_link">
    <inertial>
      <mass value="0.1"/>
      <origin xyz=" 0 0 0 "/>
      <inertia ixx="0.00012411765597" ixy="0.0" ixz="0.0" iyy="0.00015218160428" iyz="0.0" izz="0.00011763977943"/>
    </inertial>
    <collision>
      <origin rpy="-1.570795 0 0" xyz="0 0 0"/>
      <geometry>
        <cylinder length="0.0825" radius="0.085"/>
        <!--<box size="1.0 0.5 0.1" />-->
      </geometry>
      <!--<material name="MTWheelColMat"/>-->
    </collision>
  </link>
  <gazebo reference="right_0_wheel_link">
    <mu1>1.0</mu1>
    <mu2>1.0</mu2>
    <kp>1000000.0</kp>
    <kd>100.0</kd>
    <minDepth>0.001</minDepth>
    <maxVel>1.0</maxVel>
    <!--<fdir1>1 0 0</fdir1>-->
    <!--<maxVel>1.0</maxVel>-->
  </gazebo>
  <transmission name="right_0_wheel_trans" type="pr2_mechanism_model/SimpleTransmission">
    <actuator name="right_0_motor_link"/>
    <joint name="right_0_wheel_joint"/>
    <mechanicalReduction>1.0</mechanicalReduction>
    <motorTorqueConstant>1</motorTorqueConstant>
  </transmission>
  <joint name="right_1_wheel_joint" type="continuous">
    <origin rpy="0 0 0" xyz="0.0 -0.15 -0.09"/>
    <parent link="base_link"/>
    <child link="right_1_wheel_link"/>
    <axis xyz="0 1 0"/>
    <limit effort="100" velocity="100"/>
    <joint_properties damping="0.0" friction="0.0"/>
    <anchor xyz="0 0 0"/>
  </joint>
  <link name="right_1_wheel_link">
    <inertial>
      <mass value="0.1"/>
      <origin xyz=" 0 0 0 "/>
      <inertia ixx="0.00012411765597" ixy="0.0" ixz="0.0" iyy="0.00015218160428" iyz="0.0" izz="0.00011763977943"/>
    </inertial>
    <collision>
      <origin rpy="-1.570795 0 0" xyz="0 0 0"/>
      <geometry>
        <cylinder length="0.0825" radius="0.085"/>
        <!--<box size="1.0 0.5 0.1" />-->
      </geometry>
      <!--<material name="MTWheelColMat"/>-->
    </collision>
  </link>
  <gazebo reference="right_1_wheel_link">
    <mu1>1.0</mu1>
    <mu2>1.0</mu2>
    <kp>1000000.0</kp>
    <kd>100.0</kd>
    <minDepth>0.001</minDepth>
    <maxVel>1.0</maxVel>
    <!--<fdir1>1 0 0</fdir1>-->
    <!--<maxVel>1.0</maxVel>-->
  </gazebo>
  <transmission name="right_1_wheel_trans" type="pr2_mechanism_model/SimpleTransmission">
    <actuator name="right_1_motor_link"/>
    <joint name="right_1_wheel_joint"/>
    <mechanicalReduction>1.0</mechanicalReduction>
    <motorTorqueConstant>1</motorTorqueConstant>
  </transmission>
  <joint name="right_2_wheel_joint" type="continuous">
    <origin rpy="0 0 0" xyz="-0.251 -0.15 -0.085"/>
    <parent link="base_link"/>
    <child link="right_2_wheel_link"/>
    <axis xyz="0 1 0"/>
    <limit effort="100" velocity="100"/>
    <joint_properties damping="0.0" friction="0.0"/>
    <anchor xyz="0 0 0"/>
  </joint>
  <link name="right_2_wheel_link">
    <inertial>
      <mass value="0.1"/>
      <origin xyz=" 0 0 0 "/>
      <inertia ixx="0.00012411765597" ixy="0.0" ixz="0.0" iyy="0.00015218160428" iyz="0.0" izz="0.00011763977943"/>
    </inertial>
    <collision>
      <origin rpy="-1.570795 0 0" xyz="0 0 0"/>
      <geometry>
        <cylinder length="0.0825" radius="0.085"/>
        <!--<box size="1.0 0.5 0.1" />-->
      </geometry>
      <!--<material name="MTWheelColMat"/>-->
    </collision>
  </link>
  <gazebo reference="right_2_wheel_link">
    <mu1>1.0</mu1>
    <mu2>1.0</mu2>
    <kp>1000000.0</kp>
    <kd>100.0</kd>
    <minDepth>0.001</minDepth>
    <maxVel>1.0</maxVel>
    <!--<fdir1>1 0 0</fdir1>-->
    <!--<maxVel>1.0</maxVel>-->
  </gazebo>
  <transmission name="right_2_wheel_trans" type="pr2_mechanism_model/SimpleTransmission">
    <actuator name="right_2_motor_link"/>
    <joint name="right_2_wheel_joint"/>
    <mechanicalReduction>1.0</mechanicalReduction>
    <motorTorqueConstant>1</motorTorqueConstant>
  </transmission>
  <!-- 
        <tracked_wheel parent="base_link" prefix="right_3" offset_x="-0.10550" offset_y="-${base_size_y / 2}" offset_z="${wheel_offset_z_from_base_link}      " reflect="1" radius="${wheel_radius_big}" height="${wheel_size_y}" mass="${wheel_mass}"/>
        <tracked_wheel parent="base_link" prefix="right_4" offset_x=" 0.10550" offset_y="-${base_size_y / 2}" offset_z="${wheel_offset_z_from_base_link}      " reflect="1" radius="${wheel_radius_big}" height="${wheel_size_y}" mass="${wheel_mass}"/>
        <tracked_wheel parent="base_link" prefix="right_5" offset_x=" 0.00500" offset_y="-${base_size_y / 2}" offset_z="${wheel_offset_z_from_base_link+0.005}" reflect="1" radius="${wheel_radius_big}" height="${wheel_size_y}" mass="${wheel_mass}"/>
        
        <tracked_wheel parent="base_link" prefix="left_3"  offset_x=" 0.10550" offset_y=" ${base_size_y / 2}" offset_z="${wheel_offset_z_from_base_link}      " reflect="1" radius="${wheel_radius_big}" height="${wheel_size_y}" mass="${wheel_mass}"/>
        <tracked_wheel parent="base_link" prefix="left_4"  offset_x="-0.10550" offset_y=" ${base_size_y / 2}" offset_z="${wheel_offset_z_from_base_link}      " reflect="1" radius="${wheel_radius_big}" height="${wheel_size_y}" mass="${wheel_mass}"/>
        <tracked_wheel parent="base_link" prefix="left_5"  offset_x=" 0.00500" offset_y=" ${base_size_y / 2}" offset_z="${wheel_offset_z_from_base_link+0.005}" reflect="1" radius="${wheel_radius_big}" height="${wheel_size_y}" mass="${wheel_mass}"/>
        
        
                <leftJoints>left_0_wheel_joint left_1_wheel_joint left_2_wheel_joint left_3_wheel_joint left_4_wheel_joint left_5_wheel_joint</leftJoints>
                <rightJoints>right_0_wheel_joint right_1_wheel_joint right_2_wheel_joint right_3_wheel_joint right_4_wheel_joint right_5_wheel_joint</rightJoints>
        
        
         -->
  <gazebo>
    <!-- TODO: make custom plugin for this that doesn't require an imu -->
    <plugin filename="libdiffdrive_plugin_multi_wheel.so" name="diffdrive_plugin_multiwheel">
      <alwaysOn>true</alwaysOn>
      <updateRate>50.0</updateRate>
      <leftJoints>left_0_wheel_joint left_1_wheel_joint left_2_wheel_joint</leftJoints>
      <rightJoints>right_0_wheel_joint right_1_wheel_joint right_2_wheel_joint</rightJoints>
      <wheelSeparation>0.3</wheelSeparation>
      <wheelDiameter>0.17</wheelDiameter>
      <torque>50000</torque>
      <interface:position name="position_iface_2"/>
      <robotNamespace>/gvrbot</robotNamespace>
      <robotBaseFrame>base_link</robotBaseFrame>
      <commandTopic>/cmd_vel</commandTopic>
      <publishOdometryTf>1</publishOdometryTf>
      <publishOdometryMsg>1</publishOdometryMsg>
      <odometryTopic>/gvrbot/odom</odometryTopic>
      <odometryFrame>odom</odometryFrame>
    </plugin>
    <plugin filename="libgazebo_ros_p3d.so" name="p3d_base_controller">
      <alwaysOn>true</alwaysOn>
      <updateRate>50.0</updateRate>
      <bodyName>base_link</bodyName>
      <topicName>/gvrbot/ground_truth/state</topicName>
      <gaussianNoise>0.01</gaussianNoise>
      <frameName>world</frameName>
      <xyzOffsets>0 0 0</xyzOffsets>
      <rpyOffsets>0 0 0</rpyOffsets>
    </plugin>
    <plugin filename="libhector_gazebo_ros_imu.so" name="imu_controller">
      <alwaysOn>true</alwaysOn>
      <updateRate>50.0</updateRate>
      <bodyName>base_link</bodyName>
      <topicName>/gvrbot/imu_quat</topicName>
      <accelDrift>0.0 0.0 0.0</accelDrift>
      <accelGaussianNoise>0.1 0.1 0.1</accelGaussianNoise>
      <rateDrift>0.0 0.0 0.0</rateDrift>
      <rateGaussianNoise>0.05 0.05 0.05</rateGaussianNoise>
      <headingDrift>0.0</headingDrift>
      <headingGaussianNoise>0.05</headingGaussianNoise>
      <xyzOffset>0 0 0</xyzOffset>
      <rpyOffset>0 0 0</rpyOffset>
    </plugin>
  </gazebo>
  <joint name="frame_8020_joint" type="fixed">
    <origin rpy="0 0 -1.570795" xyz="0.28 0.135 -0.115"/>
    <parent link="base_link"/>
    <child link="frame8020_link"/>
  </joint>
  <link name="frame8020_link">
    <inertial>
      <origin rpy="0 0 0" xyz="0.13868 -0.31707 0.28419"/>
      <mass value="4.2785"/>
      <inertia ixx="0.11494" ixy="-6.8249E-05" ixz="-0.00030429" iyy="0.12359" iyz="-0.001274" izz="0.071887"/>
    </inertial>
    <visual>
      <origin rpy="0 0 0" xyz="0 0 0"/>
      <geometry>
        <mesh filename="package://gvrbot/models/meshes/frame_8020.STL"/>
      </geometry>
      <material name="">
        <color rgba="1 1 1 1"/>
      </material>
    </visual>
    <collision>
      <origin rpy="0 0 0" xyz="0 0 0"/>
      <geometry>
        <mesh filename="package://gvrbot/models/meshes/frame_8020.STL"/>
      </geometry>
    </collision>
  </link>
  <joint name="velodyne2_base_mount_joint" type="fixed">
    <origin rpy="0 0 0" xyz="-0.028 -0.006 0.46"/>
    <parent link="base_link"/>
    <child link="velodyne2_base_link"/>
  </joint>
  <link name="velodyne2_base_link">
    <inertial>
      <mass value="1.0"/>
      <origin xyz="0 0 0.07212"/>
      <inertia ixx="0.002188947025" ixy="0" ixz="0" iyy="0.002188947025" iyz="0" izz="0.00091036445"/>
    </inertial>
    <visual>
      <geometry>
        <mesh filename="package://velodyne_description/meshes/HDL32E_base.dae"/>
      </geometry>
    </visual>
    <collision>
      <origin rpy="0 0 0" xyz="0 0 0.07212"/>
      <geometry>
        <cylinder length="0.14424" radius="0.04267"/>
      </geometry>
    </collision>
  </link>
  <joint name="velodyne2_base_scan_joint" type="fixed">
    <origin rpy="0 0 0" xyz="0 0 0.09081"/>
    <parent link="velodyne2_base_link"/>
    <child link="velodyne2"/>
  </joint>
  <link name="velodyne2">
    <inertial>
      <mass value="0.01"/>
      <origin xyz="0 0 0"/>
      <inertia ixx="1e-7" ixy="0" ixz="0" iyy="1e-7" iyz="0" izz="1e-7"/>
    </inertial>
    <visual>
      <origin rpy="0 0 0" xyz="0 0 -0.09081"/>
      <geometry>
        <mesh filename="package://velodyne_description/meshes/HDL32E_scan.dae"/>
      </geometry>
    </visual>
  </link>
  <!-- Gazebo requires the velodyne_gazebo_plugins package -->
  <gazebo reference="velodyne2">
    <sensor name="velodyne2-HDL32E" type="ray">
      <pose>0 0 0 0 0 0</pose>
      <visualize>false</visualize>
      <update_rate>10</update_rate>
      <ray>
        <scan>
          <horizontal>
            <samples>220</samples>
            <resolution>1</resolution>
            <min_angle>-3.14159265359</min_angle>
            <max_angle>3.14159265359</max_angle>
          </horizontal>
          <vertical>
            <samples>32</samples>
            <resolution>1</resolution>
            <min_angle>-0.535292481587</min_angle>
            <max_angle> 0.186226631188</max_angle>
          </vertical>
        </scan>
        <range>
          <min>0.3</min>
          <max>131.0</max>
          <resolution>0.001</resolution>
        </range>
        <noise>
          <type>gaussian</type>
          <mean>0.0</mean>
          <stddev>0.0</stddev>
        </noise>
      </ray>
      <plugin filename="libgazebo_ros_velodyne_laser.so" name="gazebo_ros_laser_controller">
        <topicName>/velodyne_points2</topicName>
        <frameName>velodyne2</frameName>
        <min_range>0.9</min_range>
        <max_range>130.0</max_range>
        <gaussianNoise>0.008</gaussianNoise>
      </plugin>
    </sensor>
  </gazebo>
</robot>
