<?xml version="1.0"?>
<robot xmlns:xacro="http://www.ros.org/wiki/xacro">
    <xacro:include filename="$(find gvrbot)/models/robots/inertial_tensors.urdf.xacro" />
    <xacro:macro name="wheel" params="prefix *joint_pose">
        <link name="${prefix}_wheel_link">
            <collision>
                <origin xyz="0 0 0" rpy="${PI/2} 0 0" />
                <geometry>
                    <cylinder radius="${wheel_radius}" length="${wheel_width}" />
                </geometry>
            </collision>
            <inertial>
                <origin xyz="0 0 0" rpy="0 0 0" />
                <mass value="0.477" />
                <inertia ixx="0.0013" ixy="0" ixz="0" iyy="0.0024" iyz="0" izz="0.0013" />
            </inertial>
        </link>
        <gazebo reference="${prefix}_wheel_link">
        </gazebo>
        <joint name="${prefix}_wheel" type="continuous">
            <parent link="chassis_link" />
            <child link="${prefix}_wheel_link" />
            <xacro:insert_block name="joint_pose" />
            <axis xyz="0 1 0" />
        </joint>
        <!-- In reality, the robot has only two motors, one per side. However, it's more
         straightforward for Gazebo to simulate as if there's an actuator per wheel. -->
        <transmission name="${prefix}_wheel_trans">
            <type>transmission_interface/SimpleTransmission</type>
            <joint name="${prefix}_wheel">
                <hardwareInterface>hardware_interface/VelocityJointInterface</hardwareInterface>
            </joint>
            <actuator name="${prefix}_actuator">
                <mechanicalReduction>1</mechanicalReduction>
            </actuator>
        </transmission>
    </xacro:macro>
</robot>
